Workbook

Sheet 商品表
A1: *商品编码SKU | B1: 商品名称 | C1: 商品类型 | D1: 是否质检 | E1: 配件/子品信息 | F1: 库存同步时支持预拆分 | G1: 图片URL | H1: 商品分类 | I1: 颜色 | J1: 尺码 | K1: 商品条码 | L1: 开发员 | M1: 销售员 | N1: 销售状态 | O1: 单品毛重 | P1: 单品净重 | Q1: 重量单位 | R1: 长 | S1: 宽 | T1: 高 | U1: 尺寸单位 | V1: 单箱毛重 | W1: 单箱净重 | X1: 单箱重量单位 | Y1: 单箱长 | Z1: 单箱宽 | AA1: 单箱高 | AB1: 单箱尺寸单位 | AC1: 单箱数量 | AD1: 打包重量 | AE1: 打包重量单位 | AF1: 包裹长 | AG1: 包裹宽 | AH1: 包裹高 | AI1: 打包尺寸单位 | AJ1: 默认供应商 | AK1: 供应商名称 | AL1: 采购员 | AM1: 预计交期（天） | AN1: 采购单价 | AO1: 采购币种 | AP1: 最小采购量 | AQ1: 采购税率（%） | AR1: 退税税率（%） | AS1: 采购链接 | AT1: 中文报关名 | AU1: 英文报关名 | AV1: 海关编码 | AW1: 报价方式 | AX1: 报关价格 | AY1: 报关价格币种 | AZ1: 报价比例(%) | BA1: 报价最大值 | BB1: 报价最大值币种 | BC1: 出口税率（%） | BD1: 运输危险品 | BE1: 含电类型 | BF1: 申报说明 | BG1: 清关价格方式 | BH1: 清关价格 | BI1: 清关价格币种 | BJ1: 清关价格比例(%) | BK1: 清关价格最大值 | BL1: 清关价格最大值币种 | BM1: 备注名 | BN1: 简称 | BO1: 商品单位 | BP1: 默认售价 | BQ1: 售价币种 | BR1: 批发价 | BS1: 批发价币种 | BT1: 商品品牌 | BU1: UPC | BV1: ASIN | BW1: 自定义分类 | BX1: 自定义1 | BY1: 自定义2 | BZ1: 商品描述 | CA1: 英文描述 | CB1: 性能描述 | CC1: 是否关联单品成本 | CD1: 采购成本 | CE1: 采购成本币种 | CF1: 是否关联单品头程费用 | CG1: 美国：费用 | CH1: 美国：币种 | CI1: 阿拉伯联合酋长国：费用 | CJ1: 阿拉伯联合酋长国：币种 | CK1: 澳大利亚：费用 | CL1: 澳大利亚：币种 | CM1: 加拿大：费用 | CN1: 加拿大：币种 | CO1: 中国：费用 | CP1: 中国：币种 | CQ1: 德国：费用 | CR1: 德国：币种 | CS1: 西班牙：费用 | CT1: 西班牙：币种 | CU1: 法国：费用 | CV1: 法国：币种 | CW1: 印度尼西亚：费用 | CX1: 印度尼西亚：币种 | CY1: 印度：费用 | CZ1: 印度：币种 | DA1: 意大利：费用 | DB1: 意大利：币种 | DC1: 日本：费用 | DD1: 日本：币种 | DE1: 墨西哥：费用 | DF1: 墨西哥：币种 | DG1: 马来西亚：费用 | DH1: 马来西亚：币种 | DI1: 荷兰：费用 | DJ1: 荷兰：币种 | DK1: 菲律宾：费用 | DL1: 菲律宾：币种 | DM1: 俄罗斯：费用 | DN1: 俄罗斯：币种 | DO1: 沙特阿拉伯：费用 | DP1: 沙特阿拉伯：币种 | DQ1: 瑞典：费用 | DR1: 瑞典：币种 | DS1: 新加坡：费用 | DT1: 新加坡：币种 | DU1: 泰国：费用 | DV1: 泰国：币种 | DW1: 英国：费用 | DX1: 英国：币种 | DY1: 越南：费用 | DZ1: 越南：币种 | EA1: 中国台湾：费用 | EB1: 中国台湾：币种
A2: S1016_white_3XL | B2: S1016 | C2: 单品 | D2: 否 | G2: https://qianyierp.oss.aliyuncs.com/image_thumbnail/MzAxYTExMzMyYzRkZTNmZmI1YmNjNmZhZTk4YjZhOTI%3D.png | H2: 男装/男装上衣/T恤 | L2: 嘉辉 | O2: 0.2 | P2: 0.2 | Q2: KG | R2: 40 | S2: 28 | T2: 5 | U2: cm | AE2: KG | AI2: cm | AJ2: 是 | AK2: KC | AL2: 梁荣富 | AM2: 15 | AN2: 12 | AO2: CNY | AP2: 1 | AQ2: 0 | AR2: 0 | AT2: 男装 | AU2: S1016 | AW2: 按定额 | AX2: 1 | AY2: USD | BC2: 0 | BD2: NONE | BE2: -- | BP2: 0 | BQ2: USD | BS2: USD | CD2: 12 | CE2: CNY | DG2: 1.2 | DH2: CNY | DK2: 0.9 | DL2: CNY | DU2: 1 | DV2: CNY
A3: S1016_white_2XL | B3: S1016 | C3: 单品 | D3: 否 | G3: https://qianyierp.oss.aliyuncs.com/image_thumbnail/MzAxYTExMzMyYzRkZTNmZmI1YmNjNmZhZTk4YjZhOTI%3D.png | H3: 男装/男装上衣/T恤 | L3: 嘉辉 | O3: 0.2 | P3: 0.2 | Q3: KG | R3: 40 | S3: 28 | T3: 5 | U3: cm | AE3: KG | AI3: cm | AJ3: 是 | AK3: KC | AL3: 梁荣富 | AM3: 15 | AN3: 12 | AO3: CNY | AP3: 1 | AQ3: 0 | AR3: 0 | AT3: 男装 | AU3: S1016 | AW3: 按定额 | AX3: 1 | AY3: USD | BC3: 0 | BD3: NONE | BE3: -- | BP3: 0 | BQ3: USD | BS3: USD | CD3: 12 | CE3: CNY | DG3: 1.2 | DH3: CNY | DK3: 0.9 | DL3: CNY | DU3: 1 | DV3: CNY
A4: S1016_white_XL | B4: S1016 | C4: 单品 | D4: 否 | G4: https://qianyierp.oss.aliyuncs.com/image_thumbnail/MzAxYTExMzMyYzRkZTNmZmI1YmNjNmZhZTk4YjZhOTI%3D.png | H4: 男装/男装上衣/T恤 | L4: 嘉辉 | O4: 0.2 | P4: 0.2 | Q4: KG | R4: 40 | S4: 28 | T4: 5 | U4: cm | AE4: KG | AI4: cm | AJ4: 是 | AK4: KC | AL4: 梁荣富 | AM4: 15 | AN4: 12 | AO4: CNY | AP4: 1 | AQ4: 0 | AR4: 0 | AT4: 男装 | AU4: S1016 | AW4: 按定额 | AX4: 1 | AY4: USD | BC4: 0 | BD4: NONE | BE4: -- | BP4: 0 | BQ4: USD | BS4: USD | CD4: 12 | CE4: CNY | DG4: 1.2 | DH4: CNY | DK4: 0.9 | DL4: CNY | DU4: 1 | DV4: CNY
A5: S1016_white_L | B5: S1016 | C5: 单品 | D5: 否 | G5: https://qianyierp.oss.aliyuncs.com/image_thumbnail/MzAxYTExMzMyYzRkZTNmZmI1YmNjNmZhZTk4YjZhOTI%3D.png | H5: 男装/男装上衣/T恤 | L5: 嘉辉 | O5: 0.2 | P5: 0.2 | Q5: KG | R5: 40 | S5: 28 | T5: 5 | U5: cm | AE5: KG | AI5: cm | AJ5: 是 | AK5: KC | AL5: 梁荣富 | AM5: 15 | AN5: 12 | AO5: CNY | AP5: 1 | AQ5: 0 | AR5: 0 | AT5: 男装 | AU5: S1016 | AW5: 按定额 | AX5: 1 | AY5: USD | BC5: 0 | BD5: NONE | BE5: -- | BP5: 0 | BQ5: USD | BS5: USD | CD5: 12 | CE5: CNY | DG5: 1.2 | DH5: CNY | DK5: 0.9 | DL5: CNY | DU5: 1 | DV5: CNY
A6: S1016_white_M | B6: S1016 | C6: 单品 | D6: 否 | G6: https://qianyierp.oss.aliyuncs.com/image_thumbnail/MzAxYTExMzMyYzRkZTNmZmI1YmNjNmZhZTk4YjZhOTI%3D.png | H6: 男装/男装上衣/T恤 | L6: 嘉辉 | O6: 0.2 | P6: 0.2 | Q6: KG | R6: 40 | S6: 28 | T6: 5 | U6: cm | AE6: KG | AI6: cm | AJ6: 是 | AK6: KC | AL6: 梁荣富 | AM6: 15 | AN6: 12 | AO6: CNY | AP6: 1 | AQ6: 0 | AR6: 0 | AT6: 男装 | AU6: S1016 | AW6: 按定额 | AX6: 1 | AY6: USD | BC6: 0 | BD6: NONE | BE6: -- | BP6: 0 | BQ6: USD | BS6: USD | CD6: 12 | CE6: CNY | DG6: 1.2 | DH6: CNY | DK6: 0.9 | DL6: CNY | DU6: 1 | DV6: CNY
A7: S1016_black_3XL | B7: S1016 | C7: 单品 | D7: 否 | G7: https://qianyierp.oss.aliyuncs.com/image_thumbnail/YWExNWRlNWI5ZDY5Yjk1ZGFiZWEzN2FjMGU2MTUyYzQ%3D.png | H7: 男装/男装上衣/T恤 | L7: 嘉辉 | O7: 0.2 | P7: 0.2 | Q7: KG | R7: 40 | S7: 28 | T7: 5 | U7: cm | AE7: KG | AI7: cm | AJ7: 是 | AK7: KC | AL7: 梁荣富 | AM7: 15 | AN7: 12 | AO7: CNY | AP7: 1 | AQ7: 0 | AR7: 0 | AT7: 男装 | AU7: S1016 | AW7: 按定额 | AX7: 1 | AY7: USD | BC7: 0 | BD7: NONE | BE7: -- | BP7: 0 | BQ7: USD | BS7: USD | CD7: 12 | CE7: CNY | DG7: 1.2 | DH7: CNY | DK7: 0.9 | DL7: CNY | DU7: 1 | DV7: CNY
A8: S1016_black_2XL | B8: S1016 | C8: 单品 | D8: 否 | G8: https://qianyierp.oss.aliyuncs.com/image_thumbnail/YWExNWRlNWI5ZDY5Yjk1ZGFiZWEzN2FjMGU2MTUyYzQ%3D.png | H8: 男装/男装上衣/T恤 | L8: 嘉辉 | O8: 0.2 | P8: 0.2 | Q8: KG | R8: 40 | S8: 28 | T8: 5 | U8: cm | AE8: KG | AI8: cm | AJ8: 是 | AK8: KC | AL8: 梁荣富 | AM8: 15 | AN8: 12 | AO8: CNY | AP8: 1 | AQ8: 0 | AR8: 0 | AT8: 男装 | AU8: S1016 | AW8: 按定额 | AX8: 1 | AY8: USD | BC8: 0 | BD8: NONE | BE8: -- | BP8: 0 | BQ8: USD | BS8: USD | CD8: 12 | CE8: CNY | DG8: 1.2 | DH8: CNY | DK8: 0.9 | DL8: CNY | DU8: 1 | DV8: CNY
A9: S1016_black_XL | B9: S1016 | C9: 单品 | D9: 否 | G9: https://qianyierp.oss.aliyuncs.com/image_thumbnail/YWExNWRlNWI5ZDY5Yjk1ZGFiZWEzN2FjMGU2MTUyYzQ%3D.png | H9: 男装/男装上衣/T恤 | L9: 嘉辉 | O9: 0.2 | P9: 0.2 | Q9: KG | R9: 40 | S9: 28 | T9: 5 | U9: cm | AE9: KG | AI9: cm | AJ9: 是 | AK9: KC | AL9: 梁荣富 | AM9: 15 | AN9: 12 | AO9: CNY | AP9: 1 | AQ9: 0 | AR9: 0 | AT9: 男装 | AU9: S1016 | AW9: 按定额 | AX9: 1 | AY9: USD | BC9: 0 | BD9: NONE | BE9: -- | BP9: 0 | BQ9: USD | BS9: USD | CD9: 12 | CE9: CNY | DG9: 1.2 | DH9: CNY | DK9: 0.9 | DL9: CNY | DU9: 1 | DV9: CNY
A10: S1016_black_L | B10: S1016 | C10: 单品 | D10: 否 | G10: https://qianyierp.oss.aliyuncs.com/image_thumbnail/YWExNWRlNWI5ZDY5Yjk1ZGFiZWEzN2FjMGU2MTUyYzQ%3D.png | H10: 男装/男装上衣/T恤 | L10: 嘉辉 | O10: 0.2 | P10: 0.2 | Q10: KG | R10: 40 | S10: 28 | T10: 5 | U10: cm | AE10: KG | AI10: cm | AJ10: 是 | AK10: KC | AL10: 梁荣富 | AM10: 15 | AN10: 12 | AO10: CNY | AP10: 1 | AQ10: 0 | AR10: 0 | AT10: 男装 | AU10: S1016 | AW10: 按定额 | AX10: 1 | AY10: USD | BC10: 0 | BD10: NONE | BE10: -- | BP10: 0 | BQ10: USD | BS10: USD | CD10: 12 | CE10: CNY | DG10: 1.2 | DH10: CNY | DK10: 0.9 | DL10: CNY | DU10: 1 | DV10: CNY
A11: S1016_black_M | B11: S1016 | C11: 单品 | D11: 否 | G11: https://qianyierp.oss.aliyuncs.com/image_thumbnail/YWExNWRlNWI5ZDY5Yjk1ZGFiZWEzN2FjMGU2MTUyYzQ%3D.png | H11: 男装/男装上衣/T恤 | L11: 嘉辉 | O11: 0.2 | P11: 0.2 | Q11: KG | R11: 40 | S11: 28 | T11: 5 | U11: cm | AE11: KG | AI11: cm | AJ11: 是 | AK11: KC | AL11: 梁荣富 | AM11: 15 | AN11: 8 | AO11: CNY | AP11: 1 | AQ11: 0 | AR11: 0 | AT11: 男装 | AU11: S1016 | AW11: 按定额 | AX11: 1 | AY11: USD | BC11: 0 | BD11: NONE | BE11: -- | BP11: 0 | BQ11: USD | BS11: USD | CD11: 12 | CE11: CNY | DG11: 1.2 | DH11: CNY | DK11: 0.9 | DL11: CNY | DU11: 1 | DV11: CNY
A12: S537_white_M | B12: S537 | C12: 单品 | D12: 否 | G12: https://qianyierp.oss.aliyuncs.com/image_thumbnail/YWExNWRlNWI5ZDY5Yjk1ZGFiZWEzN2FjMGU2MTUyYzQ%3D.png | H12: 男装/男装上衣/T恤 | L12: 嘉辉 | O12: 0.2 | P12: 0.2 | Q12: KG | R12: 40 | S12: 28 | T12: 5 | U12: cm | AE12: KG | AI12: cm | AJ12: 是 | AK12: KC | AL12: 梁荣富 | AM12: 15 | AN12: 10 | AO12: CNY | AP12: 1 | AQ12: 0 | AR12: 0 | AT12: 男装 | AU12: S1016 | AW12: 按定额 | AX12: 1 | AY12: USD | BC12: 0 | BD12: NONE | BE12: -- | BP12: 0 | BQ12: USD | BS12: USD | CD12: 12 | CE12: CNY | DG12: 1.2 | DH12: CNY | DK12: 0.9 | DL12: CNY | DU12: 1 | DV12: CNY
A13: S537_white_L | B13: S537 | C13: 单品 | D13: 否 | G13: https://qianyierp.oss.aliyuncs.com/image_thumbnail/YWExNWRlNWI5ZDY5Yjk1ZGFiZWEzN2FjMGU2MTUyYzQ%3D.png | H13: 男装/男装上衣/T恤 | L13: 嘉辉 | O13: 0.2 | P13: 0.2 | Q13: KG | R13: 40 | S13: 28 | T13: 5 | U13: cm | AE13: KG | AI13: cm | AJ13: 是 | AK13: KC | AL13: 梁荣富 | AM13: 15 | AN13: 11 | AO13: CNY | AP13: 1 | AQ13: 0 | AR13: 0 | AT13: 男装 | AU13: S1016 | AW13: 按定额 | AX13: 1 | AY13: USD | BC13: 0 | BD13: NONE | BE13: -- | BP13: 0 | BQ13: USD | BS13: USD | CD13: 12 | CE13: CNY | DG13: 1.2 | DH13: CNY | DK13: 0.9 | DL13: CNY | DU13: 1 | DV13: CNY
... A42: S539_blue_XL | B42: S539 | C42: 单品 | D42: 否 | G42: https://qianyierp.oss.aliyuncs.com/image_thumbnail/YWExNWRlNWI5ZDY5Yjk1ZGFiZWEzN2FjMGU2MTUyYzQ%3D.png | H42: 男装/男装上衣/T恤 | L42: 嘉辉 | O42: 0.2 | P42: 0.2 | Q42: KG | R42: 40 | S42: 28 | T42: 5 | U42: cm | AE42: KG | AI42: cm | AJ42: 是 | AK42: KC | AL42: 梁荣富 | AM42: 15 | AN42: 16 | AO42: CNY | AP42: 1 | AQ42: 0 | AR42: 0 | AT42: 男装 | AU42: S1016 | AW42: 按定额 | AX42: 1 | AY42: USD | BC42: 0 | BD42: NONE | BE42: -- | BP42: 0 | BQ42: USD | BS42: USD | CD42: 12 | CE42: CNY | DG42: 1.2 | DH42: CNY | DK42: 0.9 | DL42: CNY | DU42: 1 | DV42: CNY
A43: 1839_gray_XL | B43: 1839 | C43: 单品 | D43: 否 | G43: https://qianyierp.oss.aliyuncs.com/image_thumbnail/MDdmN2M0MmVjNGNhOTYxM2E0ODVhYWRlYzc0ZWMxMjQ%3D.jpg | H43: 女装/女装裤子/工装裤/休闲裤
A44: 1839_gray_L | B44: 1839 | C44: 单品 | D44: 否 | G44: https://qianyierp.oss.aliyuncs.com/image_thumbnail/MDdmN2M0MmVjNGNhOTYxM2E0ODVhYWRlYzc0ZWMxMjQ%3D.jpg | H44: 女装/女装裤子/工装裤/休闲裤
A45: 1839_gray_M | B45: 1839 | C45: 单品 | D45: 否 | G45: https://qianyierp.oss.aliyuncs.com/image_thumbnail/MDdmN2M0MmVjNGNhOTYxM2E0ODVhYWRlYzc0ZWMxMjQ%3D.jpg | H45: 女装/女装裤子/工装裤/休闲裤
A46: 1839_gray_S | B46: 1839 | C46: 单品 | D46: 否 | G46: https://qianyierp.oss.aliyuncs.com/image_thumbnail/MDdmN2M0MmVjNGNhOTYxM2E0ODVhYWRlYzc0ZWMxMjQ%3D.jpg | H46: 女装/女装裤子/工装裤/休闲裤
A47: 1839_black_XL | B47: 1839 | C47: 单品 | D47: 否 | G47: https://qianyierp.oss.aliyuncs.com/image_thumbnail/MTM5NjMwMDc1YzJkMmIzOWJiYmJmYjkwNDQyNjQwODE%3D.png | H47: 女装/女装裤子/工装裤/休闲裤
A48: 1839_black_L | B48: 1839 | C48: 单品 | D48: 否 | G48: https://qianyierp.oss.aliyuncs.com/image_thumbnail/MTM5NjMwMDc1YzJkMmIzOWJiYmJmYjkwNDQyNjQwODE%3D.png | H48: 女装/女装裤子/工装裤/休闲裤
A49: 1839_black_M | B49: 1839 | C49: 单品 | D49: 否 | G49: https://qianyierp.oss.aliyuncs.com/image_thumbnail/MTM5NjMwMDc1YzJkMmIzOWJiYmJmYjkwNDQyNjQwODE%3D.png | H49: 女装/女装裤子/工装裤/休闲裤
A50: 1839_black_S | B50: 1839 | C50: 单品 | D50: 否 | G50: https://qianyierp.oss.aliyuncs.com/image_thumbnail/MTM5NjMwMDc1YzJkMmIzOWJiYmJmYjkwNDQyNjQwODE%3D.png | H50: 女装/女装裤子/工装裤/休闲裤
A51: 1100_white_XL | B51: 1100 | C51: 单品 | D51: 否 | G51: https://qianyierp.oss.aliyuncs.com/image_thumbnail/ZDExNTg1MmZkZWM5OGNjNWJjMjVhMTUyM2ZmZTQ1YmE%3D.jpg | H51: 女装/女装裙子/牛奶丝连衣裙
A52: 1100_white_L | B52: 1100 | C52: 单品 | D52: 否 | G52: https://qianyierp.oss.aliyuncs.com/image_thumbnail/ZDExNTg1MmZkZWM5OGNjNWJjMjVhMTUyM2ZmZTQ1YmE%3D.jpg | H52: 女装/女装裙子/牛奶丝连衣裙
A53: 1100_white_M | B53: 1100 | C53: 单品 | D53: 否 | G53: https://qianyierp.oss.aliyuncs.com/image_thumbnail/ZDExNTg1MmZkZWM5OGNjNWJjMjVhMTUyM2ZmZTQ1YmE%3D.jpg | H53: 女装/女装裙子/牛奶丝连衣裙
A54: 1100_white_S | B54: 1100 | C54: 单品 | D54: 否 | G54: https://qianyierp.oss.aliyuncs.com/image_thumbnail/ZDExNTg1MmZkZWM5OGNjNWJjMjVhMTUyM2ZmZTQ1YmE%3D.jpg | H54: 女装/女装裙子/牛奶丝连衣裙
... A76: 9630_blue_160 | B76: 9630 | C76: 单品 | D76: 否 | G76: https://qianyierp.oss.aliyuncs.com/image_thumbnail/M2QwYmE1YWJmNWZkODI3YzNjY2QyNmNmYWE4ODJiZGU%3D.jpg | H76: 童装/童装套装/
A77: S730_navyblue_3XL | B77: S730 | C77: 单品 | D77: 否 | G77: https://qianyierp.oss.aliyuncs.com/image_thumbnail/M2JjZGY3ZDU4M2E5MTJiYmZjZDhhZWE3OTFlYmE3ZWM%3D.png | H77: 男装/男装上衣/长袖
A78: S730_navyblue_2XL | B78: S730 | C78: 单品 | D78: 否 | G78: https://qianyierp.oss.aliyuncs.com/image_thumbnail/M2JjZGY3ZDU4M2E5MTJiYmZjZDhhZWE3OTFlYmE3ZWM%3D.png | H78: 男装/男装上衣/长袖
A79: S730_navyblue_XL | B79: S730 | C79: 单品 | D79: 否 | G79: https://qianyierp.oss.aliyuncs.com/image_thumbnail/M2JjZGY3ZDU4M2E5MTJiYmZjZDhhZWE3OTFlYmE3ZWM%3D.png | H79: 男装/男装上衣/长袖
A80: S730_navyblue_L | B80: S730 | C80: 单品 | D80: 否 | G80: https://qianyierp.oss.aliyuncs.com/image_thumbnail/M2JjZGY3ZDU4M2E5MTJiYmZjZDhhZWE3OTFlYmE3ZWM%3D.png | H80: 男装/男装上衣/长袖
A81: S730_navyblue_M | B81: S730 | C81: 单品 | D81: 否 | G81: https://qianyierp.oss.aliyuncs.com/image_thumbnail/M2JjZGY3ZDU4M2E5MTJiYmZjZDhhZWE3OTFlYmE3ZWM%3D.png | H81: 男装/男装上衣/长袖
A82: S730_darkgray_3XL | B82: S730 | C82: 单品 | D82: 否 | G82: https://qianyierp.oss.aliyuncs.com/image_thumbnail/M2JjZGY3ZDU4M2E5MTJiYmZjZDhhZWE3OTFlYmE3ZWM%3D.png | H82: 男装/男装上衣/长袖
A83: S730_darkgray_2XL | B83: S730 | C83: 单品 | D83: 否 | G83: https://qianyierp.oss.aliyuncs.com/image_thumbnail/M2JjZGY3ZDU4M2E5MTJiYmZjZDhhZWE3OTFlYmE3ZWM%3D.png | H83: 男装/男装上衣/长袖
A84: S730_darkgray_XL | B84: S730 | C84: 单品 | D84: 否 | G84: https://qianyierp.oss.aliyuncs.com/image_thumbnail/M2JjZGY3ZDU4M2E5MTJiYmZjZDhhZWE3OTFlYmE3ZWM%3D.png | H84: 男装/男装上衣/长袖
A85: S730_darkgray_L | B85: S730 | C85: 单品 | D85: 否 | G85: https://qianyierp.oss.aliyuncs.com/image_thumbnail/M2JjZGY3ZDU4M2E5MTJiYmZjZDhhZWE3OTFlYmE3ZWM%3D.png | H85: 男装/男装上衣/长袖
A86: S730_darkgray_M | B86: S730 | C86: 单品 | D86: 否 | G86: https://qianyierp.oss.aliyuncs.com/image_thumbnail/M2JjZGY3ZDU4M2E5MTJiYmZjZDhhZWE3OTFlYmE3ZWM%3D.png | H86: 男装/男装上衣/长袖
A87: 1285_red_XL | B87: 1285 | C87: 单品 | D87: 否 | G87: https://qianyierp.oss.aliyuncs.com/image_thumbnail/MTUyMDc4ODI5ODQzNTJlYzM0NjkzZjE4ODcwYjBiNDU%3D.jpg | H87: 女装/女装裙子/牛奶丝连衣裙
A88: 1285_red_L | B88: 1285 | C88: 单品 | D88: 否 | G88: https://qianyierp.oss.aliyuncs.com/image_thumbnail/MTUyMDc4ODI5ODQzNTJlYzM0NjkzZjE4ODcwYjBiNDU%3D.jpg | H88: 女装/女装裙子/牛奶丝连衣裙
A89: 1285_red_M | B89: 1285 | C89: 单品 | D89: 否 | G89: https://qianyierp.oss.aliyuncs.com/image_thumbnail/MTUyMDc4ODI5ODQzNTJlYzM0NjkzZjE4ODcwYjBiNDU%3D.jpg | H89: 女装/女装裙子/牛奶丝连衣裙
...

Sheet 发货清单-原始
A1: 订单ID | B1: 运输方式 | C1: 国家 | D1: 包裹编号 | E1: 货号 | F1: 颜色 | G1: 尺码 | H1: 数量 | I1: 发货日期 | J1: 唛头
A2: ORDER001 | B2: 海运 | C2: 泰国 | D2: 1 | E2: S537 | F2: 白色 | G2: M | H2: 53 | I2: 45987 | J2: 2125-52
A3: ORDER001 | B3: 海运 | C3: 马来西亚 | D3: 1 | E3: S537 | F3: 白色 | G3: L | H3: 99 | I3: 45987 | J3: 2125-52
A4: ORDER001 | B4: 海运 | C4: 马来西亚 | D4: 1 | E4: S537 | F4: 黑色 | G4: L | H4: 68 | I4: 45987 | J4: 2125-52
A5: ORDER001 | B5: 海运 | C5: 马来西亚 | D5: 1 | E5: S537 | F5: 黑色 | G5: 2XL | H5: 68 | I5: 45987 | J5: 2125-52
A6: ORDER001 | B6: 海运 | C6: 马来西亚 | D6: 1 | E6: S537 | F6: 黑色 | G6: 3XL | H6: 69 | I6: 45987 | J6: 2125-52
A7: ORDER001 | B7: 海运 | C7: 马来西亚 | D7: 2 | E7: S537 | F7: 黑色 | G7: 3XL | H7: 50 | I7: 45987 | J7: 2125-52
A8: ORDER001 | B8: 海运 | C8: 马来西亚 | D8: 2 | E8: S596 | F8: 灰色 | G8: L | H8: 272 | I8: 45987 | J8: 2125-52
A9: ORDER001 | B9: 陆运 | C9: 马来西亚 | D9: 1 | E9: S537 | F9: 白色 | G9: 3XL | H9: 92 | I9: 45987 | J9: 2125-52
A10: ORDER001 | B10: 陆运 | C10: 马来西亚 | D10: 1 | E10: S671 | F10: 黑色 | G10: M | H10: 98 | I10: 45987 | J10: 2125-52
A11: ORDER001 | B11: 陆运 | C11: 马来西亚 | D11: 1 | E11: S671 | F11: 黑色 | G11: L | H11: 100 | I11: 45987 | J11: 2125-52
A12: ORDER001 | B12: 陆运 | C12: 马来西亚 | D12: 1 | E12: S671 | F12: 黑色 | G12: 2XL | H12: 10 | I12: 45987 | J12: 2125-52
A13: ORDER001 | B13: 陆运 | C13: 马来西亚 | D13: 2 | E13: S671 | F13: 黑色 | G13: 2XL | H13: 140 | I13: 45987 | J13: 2125-52
... A211: ORDER003 | B211: 陆运 | C211: 马来西亚 | D211: 11 | E211: S596 | F211: 藏青 | G211: L | H211: 190 | I211: 45987 | J211: 2125-52

Sheet 对账单-原始
A1: 订单ID | B1: 日期 | C1: 款式 | D1: 数量 | E1: 单价 | F1: 金额 | G1: 类型
A2: ORDER001 | B2: 45987 | C2: 596色布 | D2: 2050 | E2: 22 | F2: 45100 | G2: 发货
A3: ORDER001 | B3: 45987 | C3: S537 | D3: 499 | E3: 33 | F3: 16467 | G3: 发货
A4: ORDER001 | B4: 45987 | C4: S671黑色 | D4: 348 | E4: 25 | F4: 8700 | G4: 发货
A5: ORDER001 | B5: 45987 | C5: S546黑色 | D5: 204 | E5: 32 | F5: 6528 | G5: 发货
A6: ORDER001 | B6: 45987 | C6: S539 | D6: 169 | E6: 12 | F6: 2028 | G6: 发货
A7: ORDER001 | B7: 45987 | C7: S568 | D7: 198 | E7: 26 | F7: 5148 | G7: 发货
A8: ORDER001 | B8: 45987 | C8: S516 | D8: 237 | E8: 22 | F8: 5214 | G8: 发货
A9: ORDER001 | B9: 45987 | C9: S533 | D9: 137 | E9: 23 | F9: 3151 | G9: 发货
A10: ORDER001 | B10: 45987 | C10: 退CK22差价 | D10: 75 | E10: 12 | F10: 900 | G10: 退货
A11: ORDER001 | B11: 45987 | C11: 运费 | D11: 1 | E11: 150 | F11: 150 | G11: 运费
A12: ORDER002 | B12: 45987 | C12: 596色布 | D12: 2050 | E12: 22 | F12: 45100 | G12: 发货
A13: ORDER002 | B13: 45987 | C13: S537 | D13: 499 | E13: 33 | F13: 16467 | G13: 发货
... A51: ORDER003 | B51: 45987 | C51: 运费 | D51: 1 | E51: 150 | F51: 150 | G51: 运费

Sheet 颜色对照表
A1: 中文颜色 | B1: 中文颜色简写 | C1: 英文颜色
A2: 白色 | B2: 白 | C2: white
A3: 黑色 | B3: 黑 | C3: black
A4: 灰色 | B4: 灰 | C4: gray
A5: 深灰色 | B5: 深灰 | C5: darkgray
A6: 米白色 | B6: 米白 | C6: offwhite
A7: 蓝色 | B7: 蓝 | C7: blue
A8: 棕色 | B8: 棕 | C8: brown
A9: 粉色 | B9: 粉 | C9: pink
A10: 海军蓝 | B10: 海军蓝 | C10: navyblue
A11: 红色 | B11: 红 | C11: red
A12: 杏色 | B12: 杏 | C12: apricot
... A16: 藏青 | B16: 藏青 | C16: navyblue

Sheet 发货明细 -demo
A1: 订单ID | B1: 运输方式 | C1: 国家 | D1: 包裹编号 | E1: 货号 | F1: 颜色 | G1: 尺码 | H1: 数量 | I1: 发货日期 | J1: 唛头 | K1: 英文颜色 | L1: 商品编码 | M1: 工厂单价 | N1: 头程费用
A2: ORDER001 | B2: 海运 | C2: 泰国 | D2: 1 | E2: S537 | F2: 白色 | G2: M | H2: 53 | I2: 45987 | J2: 2125-52 | K2: {=IFERROR( XLOOKUP(F2, '颜色对照表'!A:A, '颜色对照表'!C:C), IFERROR( XLOOKUP(F2, '颜色对照表'!B:B, '颜色对照表'!C:C), "未匹配到颜色" ) )} -> white | L2: =E2&"_"&K2&"_"&G2 -> S537_white_M | M2: =IFERROR(__xludf.DUMMYFUNCTION("INDEX(FILTER('对账单'!$E$2:$E1000, '对账单'!$A$2:$A1000 = A2, '对账单'!$G$2:$G1000 = E2),1)"),33.0) -> 33 | N2: =IFERROR(__xludf.DUMMYFUNCTION("IFERROR( INDEX( FILTER('商品表'!$A:$IV, '商品表'!$A:$A = L2), 1, MATCH(C2 & ""：费用"", '商品表'!$1:$1, 0) ), ""无数据"" ) "),1.0) -> 1
A3: ORDER001 | B3: 海运 | C3: 马来西亚 | D3: 1 | E3: S537 | F3: 白色 | G3: L | H3: 99 | I3: 45987 | J3: 2125-52 | K3: {=IFERROR( XLOOKUP(F3, '颜色对照表'!A:A, '颜色对照表'!C:C), IFERROR( XLOOKUP(F3, '颜色对照表'!B:B, '颜色对照表'!C:C), "未匹配到颜色" ) )} -> white | L3: =E3&"_"&K3&"_"&G3 -> S537_white_L | M3: =IFERROR(__xludf.DUMMYFUNCTION("INDEX(FILTER('对账单'!$E$2:$E1000, '对账单'!$A$2:$A1000 = A3, '对账单'!$G$2:$G1000 = E3),1)"),33.0) -> 33 | N3: =IFERROR(__xludf.DUMMYFUNCTION("IFERROR( INDEX( FILTER('商品表'!$A:$IV, '商品表'!$A:$A = L3), 1, MATCH(C3 & ""：费用"", '商品表'!$1:$1, 0) ), ""无数据"" ) "),1.2) -> 1.2
A4: ORDER001 | B4: 海运 | C4: 马来西亚 | D4: 1 | E4: S537 | F4: 黑色 | G4: L | H4: 68 | I4: 45987 | J4: 2125-52 | K4: {=IFERROR( XLOOKUP(F4, '颜色对照表'!A:A, '颜色对照表'!C:C), IFERROR( XLOOKUP(F4, '颜色对照表'!B:B, '颜色对照表'!C:C), "未匹配到颜色" ) )} -> black | L4: =E4&"_"&K4&"_"&G4 -> S537_black_L | M4: =IFERROR(__xludf.DUMMYFUNCTION("INDEX(FILTER('对账单'!$E$2:$E1000, '对账单'!$A$2:$A1000 = A4, '对账单'!$G$2:$G1000 = E4),1)"),33.0) -> 33 | N4: =IFERROR(__xludf.DUMMYFUNCTION("IFERROR( INDEX( FILTER('商品表'!$A:$IV, '商品表'!$A:$A = L4), 1, MATCH(C4 & ""：费用"", '商品表'!$1:$1, 0) ), ""无数据"" ) "),1.2) -> 1.2
A5: ORDER001 | B5: 海运 | C5: 马来西亚 | D5: 1 | E5: S537 | F5: 黑色 | G5: 2XL | H5: 68 | I5: 45987 | J5: 2125-52 | K5: {=IFERROR( XLOOKUP(F5, '颜色对照表'!A:A, '颜色对照表'!C:C), IFERROR( XLOOKUP(F5, '颜色对照表'!B:B, '颜色对照表'!C:C), "未匹配到颜色" ) )} -> black | L5: =E5&"_"&K5&"_"&G5 -> S537_black_2XL | M5: =IFERROR(__xludf.DUMMYFUNCTION("INDEX(FILTER('对账单'!$E$2:$E1000, '对账单'!$A$2:$A1000 = A5, '对账单'!$G$2:$G1000 = E5),1)"),33.0) -> 33 | N5: =IFERROR(__xludf.DUMMYFUNCTION("IFERROR( INDEX( FILTER('商品表'!$A:$IV, '商品表'!$A:$A = L5), 1, MATCH(C5 & ""：费用"", '商品表'!$1:$1, 0) ), ""无数据"" ) "),1.2) -> 1.2
A6: ORDER001 | B6: 海运 | C6: 马来西亚 | D6: 1 | E6: S537 | F6: 黑色 | G6: 3XL | H6: 69 | I6: 45987 | J6: 2125-52 | K6: {=IFERROR( XLOOKUP(F6, '颜色对照表'!A:A, '颜色对照表'!C:C), IFERROR( XLOOKUP(F6, '颜色对照表'!B:B, '颜色对照表'!C:C), "未匹配到颜色" ) )} -> black | L6: =E6&"_"&K6&"_"&G6 -> S537_black_3XL | M6: =IFERROR(__xludf.DUMMYFUNCTION("INDEX(FILTER('对账单'!$E$2:$E1000, '对账单'!$A$2:$A1000 = A6, '对账单'!$G$2:$G1000 = E6),1)"),33.0) -> 33 | N6: =IFERROR(__xludf.DUMMYFUNCTION("IFERROR( INDEX( FILTER('商品表'!$A:$IV, '商品表'!$A:$A = L6), 1, MATCH(C6 & ""：费用"", '商品表'!$1:$1, 0) ), ""无数据"" ) "),1.2) -> 1.2
A7: ORDER001 | B7: 海运 | C7: 马来西亚 | D7: 2 | E7: S537 | F7: 黑色 | G7: 3XL | H7: 50 | I7: 45987 | J7: 2125-52 | K7: {=IFERROR( XLOOKUP(F7, '颜色对照表'!A:A, '颜色对照表'!C:C), IFERROR( XLOOKUP(F7, '颜色对照表'!B:B, '颜色对照表'!C:C), "未匹配到颜色" ) )} -> black | L7: =E7&"_"&K7&"_"&G7 -> S537_black_3XL | M7: =IFERROR(__xludf.DUMMYFUNCTION("INDEX(FILTER('对账单'!$E$2:$E1000, '对账单'!$A$2:$A1000 = A7, '对账单'!$G$2:$G1000 = E7),1)"),33.0) -> 33 | N7: =IFERROR(__xludf.DUMMYFUNCTION("IFERROR( INDEX( FILTER('商品表'!$A:$IV, '商品表'!$A:$A = L7), 1, MATCH(C7 & ""：费用"", '商品表'!$1:$1, 0) ), ""无数据"" ) "),1.2) -> 1.2
A8: ORDER001 | B8: 海运 | C8: 马来西亚 | D8: 2 | E8: S596 | F8: 灰色 | G8: L | H8: 272 | I8: 45987 | J8: 2125-52 | K8: {=IFERROR( XLOOKUP(F8, '颜色对照表'!A:A, '颜色对照表'!C:C), IFERROR( XLOOKUP(F8, '颜色对照表'!B:B, '颜色对照表'!C:C), "未匹配到颜色" ) )} -> gray | L8: =E8&"_"&K8&"_"&G8 -> S596_gray_L | M8: =IFERROR(__xludf.DUMMYFUNCTION("INDEX(FILTER('对账单'!$E$2:$E1000, '对账单'!$A$2:$A1000 = A8, '对账单'!$G$2:$G1000 = E8),1)"),"#N/A") -> #N/A | N8: =IFERROR(__xludf.DUMMYFUNCTION("IFERROR( INDEX( FILTER('商品表'!$A:$IV, '商品表'!$A:$A = L8), 1, MATCH(C8 & ""：费用"", '商品表'!$1:$1, 0) ), ""无数据"" ) "),1.2) -> 1.2
A9: ORDER001 | B9: 陆运 | C9: 马来西亚 | D9: 1 | E9: S537 | F9: 白色 | G9: 3XL | H9: 92 | I9: 45987 | J9: 2125-52 | K9: {=IFERROR( XLOOKUP(F9, '颜色对照表'!A:A, '颜色对照表'!C:C), IFERROR( XLOOKUP(F9, '颜色对照表'!B:B, '颜色对照表'!C:C), "未匹配到颜色" ) )} -> white | L9: =E9&"_"&K9&"_"&G9 -> S537_white_3XL | M9: =IFERROR(__xludf.DUMMYFUNCTION("INDEX(FILTER('对账单'!$E$2:$E1000, '对账单'!$A$2:$A1000 = A9, '对账单'!$G$2:$G1000 = E9),1)"),33.0) -> 33 | N9: =IFERROR(__xludf.DUMMYFUNCTION("IFERROR( INDEX( FILTER('商品表'!$A:$IV, '商品表'!$A:$A = L9), 1, MATCH(C9 & ""：费用"", '商品表'!$1:$1, 0) ), ""无数据"" ) "),1.2) -> 1.2
A10: ORDER001 | B10: 陆运 | C10: 马来西亚 | D10: 1 | E10: S671 | F10: 黑色 | G10: M | H10: 98 | I10: 45987 | J10: 2125-52 | K10: {=IFERROR( XLOOKUP(F10, '颜色对照表'!A:A, '颜色对照表'!C:C), IFERROR( XLOOKUP(F10, '颜色对照表'!B:B, '颜色对照表'!C:C), "未匹配到颜色" ) )} -> black | L10: =E10&"_"&K10&"_"&G10 -> S671_black_M | M10: =IFERROR(__xludf.DUMMYFUNCTION("INDEX(FILTER('对账单'!$E$2:$E1000, '对账单'!$A$2:$A1000 = A10, '对账单'!$G$2:$G1000 = E10),1)"),25.0) -> 25 | N10: =IFERROR(__xludf.DUMMYFUNCTION("IFERROR( INDEX( FILTER('商品表'!$A:$IV, '商品表'!$A:$A = L10), 1, MATCH(C10 & ""：费用"", '商品表'!$1:$1, 0) ), ""无数据"" ) "),1.2) -> 1.2
A11: ORDER001 | B11: 陆运 | C11: 马来西亚 | D11: 1 | E11: S671 | F11: 黑色 | G11: L | H11: 100 | I11: 45987 | J11: 2125-52 | K11: {=IFERROR( XLOOKUP(F11, '颜色对照表'!A:A, '颜色对照表'!C:C), IFERROR( XLOOKUP(F11, '颜色对照表'!B:B, '颜色对照表'!C:C), "未匹配到颜色" ) )} -> black | L11: =E11&"_"&K11&"_"&G11 -> S671_black_L | M11: =IFERROR(__xludf.DUMMYFUNCTION("INDEX(FILTER('对账单'!$E$2:$E1000, '对账单'!$A$2:$A1000 = A11, '对账单'!$G$2:$G1000 = E11),1)"),25.0) -> 25 | N11: =IFERROR(__xludf.DUMMYFUNCTION("IFERROR( INDEX( FILTER('商品表'!$A:$IV, '商品表'!$A:$A = L11), 1, MATCH(C11 & ""：费用"", '商品表'!$1:$1, 0) ), ""无数据"" ) "),1.2) -> 1.2
A12: ORDER001 | B12: 陆运 | C12: 马来西亚 | D12: 1 | E12: S671 | F12: 黑色 | G12: 2XL | H12: 10 | I12: 45987 | J12: 2125-52 | K12: {=IFERROR( XLOOKUP(F12, '颜色对照表'!A:A, '颜色对照表'!C:C), IFERROR( XLOOKUP(F12, '颜色对照表'!B:B, '颜色对照表'!C:C), "未匹配到颜色" ) )} -> black | L12: =E12&"_"&K12&"_"&G12 -> S671_black_2XL | M12: =IFERROR(__xludf.DUMMYFUNCTION("INDEX(FILTER('对账单'!$E$2:$E1000, '对账单'!$A$2:$A1000 = A12, '对账单'!$G$2:$G1000 = E12),1)"),25.0) -> 25 | N12: =IFERROR(__xludf.DUMMYFUNCTION("IFERROR( INDEX( FILTER('商品表'!$A:$IV, '商品表'!$A:$A = L12), 1, MATCH(C12 & ""：费用"", '商品表'!$1:$1, 0) ), ""无数据"" ) "),1.2) -> 1.2
A13: ORDER001 | B13: 陆运 | C13: 马来西亚 | D13: 2 | E13: S671 | F13: 黑色 | G13: 2XL | H13: 140 | I13: 45987 | J13: 2125-52 | K13: {=IFERROR( XLOOKUP(F13, '颜色对照表'!A:A, '颜色对照表'!C:C), IFERROR( XLOOKUP(F13, '颜色对照表'!B:B, '颜色对照表'!C:C), "未匹配到颜色" ) )} -> black | L13: =E13&"_"&K13&"_"&G13 -> S671_black_2XL | M13: =IFERROR(__xludf.DUMMYFUNCTION("INDEX(FILTER('对账单'!$E$2:$E1000, '对账单'!$A$2:$A1000 = A13, '对账单'!$G$2:$G1000 = E13),1)"),25.0) -> 25 | N13: =IFERROR(__xludf.DUMMYFUNCTION("IFERROR( INDEX( FILTER('商品表'!$A:$IV, '商品表'!$A:$A = L13), 1, MATCH(C13 & ""：费用"", '商品表'!$1:$1, 0) ), ""无数据"" ) "),1.2) -> 1.2
A14: ORDER001 | B14: 陆运 | C14: 马来西亚 | D14: 2 | E14: S546 | F14: 黑色 | G14: M | H14: 65 | I14: 45987 | J14: 2125-52 | K14: {=IFERROR( XLOOKUP(F14, '颜色对照表'!A:A, '颜色对照表'!C:C), IFERROR( XLOOKUP(F14, '颜色对照表'!B:B, '颜色对照表'!C:C), "未匹配到颜色" ) )} -> black | L14: =E14&"_"&K14&"_"&G14 -> S546_black_M | M14: =IFERROR(__xludf.DUMMYFUNCTION("INDEX(FILTER('对账单'!$E$2:$E1000, '对账单'!$A$2:$A1000 = A14, '对账单'!$G$2:$G1000 = E14),1)"),32.0) -> 32 | N14: =IFERROR(__xludf.DUMMYFUNCTION("IFERROR( INDEX( FILTER('商品表'!$A:$IV, '商品表'!$A:$A = L14), 1, MATCH(C14 & ""：费用"", '商品表'!$1:$1, 0) ), ""无数据"" ) "),1.2) -> 1.2
A15: ORDER001 | B15: 陆运 | C15: 马来西亚 | D15: 2 | E15: S546 | F15: 黑色 | G15: L | H15: 69 | I15: 45987 | J15: 2125-52 | K15: {=IFERROR( XLOOKUP(F15, '颜色对照表'!A:A, '颜色对照表'!C:C), IFERROR( XLOOKUP(F15, '颜色对照表'!B:B, '颜色对照表'!C:C), "未匹配到颜色" ) )} -> black | L15: =E15&"_"&K15&"_"&G15 -> S546_black_L | M15: =IFERROR(__xludf.DUMMYFUNCTION("INDEX(FILTER('对账单'!$E$2:$E1000, '对账单'!$A$2:$A1000 = A15, '对账单'!$G$2:$G1000 = E15),1)"),32.0) -> 32 | N15: =IFERROR(__xludf.DUMMYFUNCTION("IFERROR( INDEX( FILTER('商品表'!$A:$IV, '商品表'!$A:$A = L15), 1, MATCH(C15 & ""：费用"", '商品表'!$1:$1, 0) ), ""无数据"" ) "),1.2) -> 1.2
A16: ORDER001 | B16: 陆运 | C16: 马来西亚 | D16: 3 | E16: S546 | F16: 黑色 | G16: XL | H16: 70 | I16: 45987 | J16: 2125-52 | K16: {=IFERROR( XLOOKUP(F16, '颜色对照表'!A:A, '颜色对照表'!C:C), IFERROR( XLOOKUP(F16, '颜色对照表'!B:B, '颜色对照表'!C:C), "未匹配到颜色" ) )} -> black | L16: =E16&"_"&K16&"_"&G16 -> S546_black_XL | M16: =IFERROR(__xludf.DUMMYFUNCTION("INDEX(FILTER('对账单'!$E$2:$E1000, '对账单'!$A$2:$A1000 = A16, '对账单'!$G$2:$G1000 = E16),1)"),32.0) -> 32 | N16: =IFERROR(__xludf.DUMMYFUNCTION("IFERROR( INDEX( FILTER('商品表'!$A:$IV, '商品表'!$A:$A = L16), 1, MATCH(C16 & ""：费用"", '商品表'!$1:$1, 0) ), ""无数据"" ) "),1.2) -> 1.2
A17: ORDER001 | B17: 陆运 | C17: 马来西亚 | D17: 3 | E17: S539 | F17: 黑色 | G17: L | H17: 80 | I17: 45987 | J17: 2125-52 | K17: {=IFERROR( XLOOKUP(F17, '颜色对照表'!A:A, '颜色对照表'!C:C), IFERROR( XLOOKUP(F17, '颜色对照表'!B:B, '颜色对照表'!C:C), "未匹配到颜色" ) )} -> black | L17: =E17&"_"&K17&"_"&G17 -> S539_black_L | M17: =IFERROR(__xludf.DUMMYFUNCTION("INDEX(FILTER('对账单'!$E$2:$E1000, '对账单'!$A$2:$A1000 = A17, '对账单'!$G$2:$G1000 = E17),1)"),12.0) -> 12 | N17: =IFERROR(__xludf.DUMMYFUNCTION("IFERROR( INDEX( FILTER('商品表'!$A:$IV, '商品表'!$A:$A = L17), 1, MATCH(C17 & ""：费用"", '商品表'!$1:$1, 0) ), ""无数据"" ) "),1.2) -> 1.2
A18: ORDER001 | B18: 陆运 | C18: 马来西亚 | D18: 3 | E18: S568 | F18: 深灰 | G18: XL | H18: 77 | I18: 45987 | J18: 2125-52 | K18: {=IFERROR( XLOOKUP(F18, '颜色对照表'!A:A, '颜色对照表'!C:C), IFERROR( XLOOKUP(F18, '颜色对照表'!B:B, '颜色对照表'!C:C), "未匹配到颜色" ) )} -> darkgray | L18: =E18&"_"&K18&"_"&G18 -> S568_darkgray_XL | M18: =IFERROR(__xludf.DUMMYFUNCTION("INDEX(FILTER('对账单'!$E$2:$E1000, '对账单'!$A$2:$A1000 = A18, '对账单'!$G$2:$G1000 = E18),1)"),26.0) -> 26 | N18: =IFERROR(__xludf.DUMMYFUNCTION("IFERROR( INDEX( FILTER('商品表'!$A:$IV, '商品表'!$A:$A = L18), 1, MATCH(C18 & ""：费用"", '商品表'!$1:$1, 0) ), ""无数据"" ) "),1.2) -> 1.2
A19: ORDER001 | B19: 陆运 | C19: 马来西亚 | D19: 3 | E19: S568 | F19: 深灰 | G19: 2XL | H19: 40 | I19: 45987 | J19: 2125-52 | K19: {=IFERROR( XLOOKUP(F19, '颜色对照表'!A:A, '颜色对照表'!C:C), IFERROR( XLOOKUP(F19, '颜色对照表'!B:B, '颜色对照表'!C:C), "未匹配到颜色" ) )} -> darkgray | L19: =E19&"_"&K19&"_"&G19 -> S568_darkgray_2XL | M19: =IFERROR(__xludf.DUMMYFUNCTION("INDEX(FILTER('对账单'!$E$2:$E1000, '对账单'!$A$2:$A1000 = A19, '对账单'!$G$2:$G1000 = E19),1)"),26.0) -> 26 | N19: =IFERROR(__xludf.DUMMYFUNCTION("IFERROR( INDEX( FILTER('商品表'!$A:$IV, '商品表'!$A:$A = L19), 1, MATCH(C19 & ""：费用"", '商品表'!$1:$1, 0) ), ""无数据"" ) "),1.2) -> 1.2
A20: ORDER001 | B20: 陆运 | C20: 马来西亚 | D20: 3 | E20: S568 | F20: 深灰 | G20: 3XL | H20: 21 | I20: 45987 | J20: 2125-52 | K20: {=IFERROR( XLOOKUP(F20, '颜色对照表'!A:A, '颜色对照表'!C:C), IFERROR( XLOOKUP(F20, '颜色对照表'!B:B, '颜色对照表'!C:C), "未匹配到颜色" ) )} -> darkgray | L20: =E20&"_"&K20&"_"&G20 -> S568_darkgray_3XL | M20: =IFERROR(__xludf.DUMMYFUNCTION("INDEX(FILTER('对账单'!$E$2:$E1000, '对账单'!$A$2:$A1000 = A20, '对账单'!$G$2:$G1000 = E20),1)"),26.0) -> 26 | N20: =IFERROR(__xludf.DUMMYFUNCTION("IFERROR( INDEX( FILTER('商品表'!$A:$IV, '商品表'!$A:$A = L20), 1, MATCH(C20 & ""：费用"", '商品表'!$1:$1, 0) ), ""无数据"" ) "),1.2) -> 1.2
A21: ORDER001 | B21: 陆运 | C21: 马来西亚 | D21: 4 | E21: S568 | F21: 深灰 | G21: 3XL | H21: 60 | I21: 45987 | J21: 2125-52 | K21: {=IFERROR( XLOOKUP(F21, '颜色对照表'!A:A, '颜色对照表'!C:C), IFERROR( XLOOKUP(F21, '颜色对照表'!B:B, '颜色对照表'!C:C), "未匹配到颜色" ) )} -> darkgray | L21: =E21&"_"&K21&"_"&G21 -> S568_darkgray_3XL | M21: =IFERROR(__xludf.DUMMYFUNCTION("INDEX(FILTER('对账单'!$E$2:$E1000, '对账单'!$A$2:$A1000 = A21, '对账单'!$G$2:$G1000 = E21),1)"),26.0) -> 26 | N21: =IFERROR(__xludf.DUMMYFUNCTION("IFERROR( INDEX( FILTER('商品表'!$A:$IV, '商品表'!$A:$A = L21), 1, MATCH(C21 & ""：费用"", '商品表'!$1:$1, 0) ), ""无数据"" ) "),1.2) -> 1.2
A22: ORDER001 | B22: 陆运 | C22: 马来西亚 | D22: 4 | E22: S596 | F22: 米白 | G22: 3XL | H22: 47 | I22: 45987 | J22: 2125-52 | K22: {=IFERROR( XLOOKUP(F22, '颜色对照表'!A:A, '颜色对照表'!C:C), IFERROR( XLOOKUP(F22, '颜色对照表'!B:B, '颜色对照表'!C:C), "未匹配到颜色" ) )} -> offwhite | L22: =E22&"_"&K22&"_"&G22 -> S596_offwhite_3XL | M22: =IFERROR(__xludf.DUMMYFUNCTION("INDEX(FILTER('对账单'!$E$2:$E1000, '对账单'!$A$2:$A1000 = A22, '对账单'!$G$2:$G1000 = E22),1)"),"#N/A") -> #N/A | N22: =IFERROR(__xludf.DUMMYFUNCTION("IFERROR( INDEX( FILTER('商品表'!$A:$IV, '商品表'!$A:$A = L22), 1, MATCH(C22 & ""：费用"", '商品表'!$1:$1, 0) ), ""无数据"" ) "),1.2) -> 1.2
A23: ORDER001 | B23: 陆运 | C23: 马来西亚 | D23: 4 | E23: S596 | F23: 米白 | G23: 2XL | H23: 47 | I23: 45987 | J23: 2125-52 | K23: {=IFERROR( XLOOKUP(F23, '颜色对照表'!A:A, '颜色对照表'!C:C), IFERROR( XLOOKUP(F23, '颜色对照表'!B:B, '颜色对照表'!C:C), "未匹配到颜色" ) )} -> offwhite | L23: =E23&"_"&K23&"_"&G23 -> S596_offwhite_2XL | M23: =IFERROR(__xludf.DUMMYFUNCTION("INDEX(FILTER('对账单'!$E$2:$E1000, '对账单'!$A$2:$A1000 = A23, '对账单'!$G$2:$G1000 = E23),1)"),"#N/A") -> #N/A | N23: =IFERROR(__xludf.DUMMYFUNCTION("IFERROR( INDEX( FILTER('商品表'!$A:$IV, '商品表'!$A:$A = L23), 1, MATCH(C23 & ""：费用"", '商品表'!$1:$1, 0) ), ""无数据"" ) "),1.2) -> 1.2
A24: ORDER001 | B24: 陆运 | C24: 马来西亚 | D24: 4 | E24: S596 | F24: 米白 | G24: L | H24: 48 | I24: 45987 | J24: 2125-52 | K24: {=IFERROR( XLOOKUP(F24, '颜色对照表'!A:A, '颜色对照表'!C:C), IFERROR( XLOOKUP(F24, '颜色对照表'!B:B, '颜色对照表'!C:C), "未匹配到颜色" ) )} -> offwhite | L24: =E24&"_"&K24&"_"&G24 -> S596_offwhite_L | M24: =IFERROR(__xludf.DUMMYFUNCTION("INDEX(FILTER('对账单'!$E$2:$E1000, '对账单'!$A$2:$A1000 = A24, '对账单'!$G$2:$G1000 = E24),1)"),"#N/A") -> #N/A | N24: =IFERROR(__xludf.DUMMYFUNCTION("IFERROR( INDEX( FILTER('商品表'!$A:$IV, '商品表'!$A:$A = L24), 1, MATCH(C24 & ""：费用"", '商品表'!$1:$1, 0) ), ""无数据"" ) "),1.2) -> 1.2
A25: ORDER001 | B25: 陆运 | C25: 马来西亚 | D25: 4 | E25: S596 | F25: 米白 | G25: M | H25: 46 | I25: 45987 | J25: 2125-52 | K25: {=IFERROR( XLOOKUP(F25, '颜色对照表'!A:A, '颜色对照表'!C:C), IFERROR( XLOOKUP(F25, '颜色对照表'!B:B, '颜色对照表'!C:C), "未匹配到颜色" ) )} -> offwhite | L25: =E25&"_"&K25&"_"&G25 -> S596_offwhite_M | M25: =IFERROR(__xludf.DUMMYFUNCTION("INDEX(FILTER('对账单'!$E$2:$E1000, '对账单'!$A$2:$A1000 = A25, '对账单'!$G$2:$G1000 = E25),1)"),"#N/A") -> #N/A | N25: =IFERROR(__xludf.DUMMYFUNCTION("IFERROR( INDEX( FILTER('商品表'!$A:$IV, '商品表'!$A:$A = L25), 1, MATCH(C25 & ""：费用"", '商品表'!$1:$1, 0) ), ""无数据"" ) "),1.2) -> 1.2
A26: ORDER001 | B26: 陆运 | C26: 马来西亚 | D26: 11 | E26: S596 | F26: 藏青 | G26: L | H26: 190 | I26: 45987 | J26: 2125-52 | K26: {=IFERROR( XLOOKUP(F26, '颜色对照表'!A:A, '颜色对照表'!C:C), IFERROR( XLOOKUP(F26, '颜色对照表'!B:B, '颜色对照表'!C:C), "未匹配到颜色" ) )} -> navyblue | L26: =E26&"_"&K26&"_"&G26 -> S596_navyblue_L | M26: =IFERROR(__xludf.DUMMYFUNCTION("INDEX(FILTER('对账单'!$E$2:$E1000, '对账单'!$A$2:$A1000 = A26, '对账单'!$G$2:$G1000 = E26),1)"),"#N/A") -> #N/A | N26: =IFERROR(__xludf.DUMMYFUNCTION("IFERROR( INDEX( FILTER('商品表'!$A:$IV, '商品表'!$A:$A = L26), 1, MATCH(C26 & ""：费用"", '商品表'!$1:$1, 0) ), ""无数据"" ) "),"无数据") -> 无数据
A27: ORDER001 | B27: 陆运 | C27: 马来西亚 | D27: 11 | E27: S596 | F27: 紫色 | G27: XL | H27: 190 | I27: 45987 | J27: 2125-52 | K27: {=IFERROR( XLOOKUP(F27, '颜色对照表'!A:A, '颜色对照表'!C:C), IFERROR( XLOOKUP(F27, '颜色对照表'!B:B, '颜色对照表'!C:C), "未匹配到颜色" ) )} -> 未匹配到颜色 | L27: =E27&"_"&K27&"_"&G27 -> S596_未匹配到颜色_XL | M27: =IFERROR(__xludf.DUMMYFUNCTION("INDEX(FILTER('对账单'!$E$2:$E1000, '对账单'!$A$2:$A1000 = A27, '对账单'!$G$2:$G1000 = E27),1)"),"#N/A") -> #N/A | N27: =IFERROR(__xludf.DUMMYFUNCTION("IFERROR( INDEX( FILTER('商品表'!$A:$IV, '商品表'!$A:$A = L27), 1, MATCH(C27 & ""：费用"", '商品表'!$1:$1, 0) ), ""无数据"" ) "),"无数据") -> 无数据
A28: ORDER001 | B28: 陆运 | C28: 马来西亚 | D28: 4 | E28: S516 | F28: 黑色 | G28: 3XL | H28: 30 | I28: 45987 | J28: 2125-52 | K28: {=IFERROR( XLOOKUP(F28, '颜色对照表'!A:A, '颜色对照表'!C:C), IFERROR( XLOOKUP(F28, '颜色对照表'!B:B, '颜色对照表'!C:C), "未匹配到颜色" ) )} -> black | L28: =E28&"_"&K28&"_"&G28 -> S516_black_3XL | M28: =IFERROR(__xludf.DUMMYFUNCTION("INDEX(FILTER('对账单'!$E$2:$E1000, '对账单'!$A$2:$A1000 = A28, '对账单'!$G$2:$G1000 = E28),1)"),22.0) -> 22 | N28: =IFERROR(__xludf.DUMMYFUNCTION("IFERROR( INDEX( FILTER('商品表'!$A:$IV, '商品表'!$A:$A = L28), 1, MATCH(C28 & ""：费用"", '商品表'!$1:$1, 0) ), ""无数据"" ) "),1.2) -> 1.2
A29: ORDER001 | B29: 陆运 | C29: 马来西亚 | D29: 5 | E29: S516 | F29: 黑色 | G29: 3XL | H29: 120 | I29: 45987 | J29: 2125-52 | K29: {=IFERROR( XLOOKUP(F29, '颜色对照表'!A:A, '颜色对照表'!C:C), IFERROR( XLOOKUP(F29, '颜色对照表'!B:B, '颜色对照表'!C:C), "未匹配到颜色" ) )} -> black | L29: =E29&"_"&K29&"_"&G29 -> S516_black_3XL | M29: =IFERROR(__xludf.DUMMYFUNCTION("INDEX(FILTER('对账单'!$E$2:$E1000, '对账单'!$A$2:$A1000 = A29, '对账单'!$G$2:$G1000 = E29),1)"),22.0) -> 22 | N29: =IFERROR(__xludf.DUMMYFUNCTION("IFERROR( INDEX( FILTER('商品表'!$A:$IV, '商品表'!$A:$A = L29), 1, MATCH(C29 & ""：费用"", '商品表'!$1:$1, 0) ), ""无数据"" ) "),1.2) -> 1.2
A30: ORDER001 | B30: 陆运 | C30: 马来西亚 | D30: 5 | E30: S516 | F30: 黑色 | G30: 2XL | H30: 57 | I30: 45987 | J30: 2125-52 | K30: {=IFERROR( XLOOKUP(F30, '颜色对照表'!A:A, '颜色对照表'!C:C), IFERROR( XLOOKUP(F30, '颜色对照表'!B:B, '颜色对照表'!C:C), "未匹配到颜色" ) )} -> black | L30: =E30&"_"&K30&"_"&G30 -> S516_black_2XL | M30: =IFERROR(__xludf.DUMMYFUNCTION("INDEX(FILTER('对账单'!$E$2:$E1000, '对账单'!$A$2:$A1000 = A30, '对账单'!$G$2:$G1000 = E30),1)"),22.0) -> 22 | N30: =IFERROR(__xludf.DUMMYFUNCTION("IFERROR( INDEX( FILTER('商品表'!$A:$IV, '商品表'!$A:$A = L30), 1, MATCH(C30 & ""：费用"", '商品表'!$1:$1, 0) ), ""无数据"" ) "),1.2) -> 1.2
A31: ORDER001 | B31: 陆运 | C31: 马来西亚 | D31: 5 | E31: S533 | F31: 黑色 | G31: 3XL | H31: 28 | I31: 45987 | J31: 2125-52 | K31: {=IFERROR( XLOOKUP(F31, '颜色对照表'!A:A, '颜色对照表'!C:C), IFERROR( XLOOKUP(F31, '颜色对照表'!B:B, '颜色对照表'!C:C), "未匹配到颜色" ) )} -> black | L31: =E31&"_"&K31&"_"&G31 -> S533_black_3XL | M31: =IFERROR(__xludf.DUMMYFUNCTION("INDEX(FILTER('对账单'!$E$2:$E1000, '对账单'!$A$2:$A1000 = A31, '对账单'!$G$2:$G1000 = E31),1)"),23.0) -> 23 | N31: =IFERROR(__xludf.DUMMYFUNCTION("IFERROR( INDEX( FILTER('商品表'!$A:$IV, '商品表'!$A:$A = L31), 1, MATCH(C31 & ""：费用"", '商品表'!$1:$1, 0) ), ""无数据"" ) "),1.2) -> 1.2
A32: ORDER001 | B32: 陆运 | C32: 马来西亚 | D32: 5 | E32: S533 | F32: 黑色 | G32: 2XL | H32: 26 | I32: 45987 | J32: 2125-52 | K32: {=IFERROR( XLOOKUP(F32, '颜色对照表'!A:A, '颜色对照表'!C:C), IFERROR( XLOOKUP(F32, '颜色对照表'!B:B, '颜色对照表'!C:C), "未匹配到颜色" ) )} -> black | L32: =E32&"_"&K32&"_"&G32 -> S533_black_2XL | M32: =IFERROR(__xludf.DUMMYFUNCTION("INDEX(FILTER('对账单'!$E$2:$E1000, '对账单'!$A$2:$A1000 = A32, '对账单'!$G$2:$G1000 = E32),1)"),23.0) -> 23 | N32: =IFERROR(__xludf.DUMMYFUNCTION("IFERROR( INDEX( FILTER('商品表'!$A:$IV, '商品表'!$A:$A = L32), 1, MATCH(C32 & ""：费用"", '商品表'!$1:$1, 0) ), ""无数据"" ) "),1.2) -> 1.2
A33: ORDER001 | B33: 陆运 | C33: 马来西亚 | D33: 5 | E33: S533 | F33: 黑色 | G33: XL | H33: 33 | I33: 45987 | J33: 2125-52 | K33: {=IFERROR( XLOOKUP(F33, '颜色对照表'!A:A, '颜色对照表'!C:C), IFERROR( XLOOKUP(F33, '颜色对照表'!B:B, '颜色对照表'!C:C), "未匹配到颜色" ) )} -> black | L33: =E33&"_"&K33&"_"&G33 -> S533_black_XL | M33: =IFERROR(__xludf.DUMMYFUNCTION("INDEX(FILTER('对账单'!$E$2:$E1000, '对账单'!$A$2:$A1000 = A33, '对账单'!$G$2:$G1000 = E33),1)"),23.0) -> 23 | N33: =IFERROR(__xludf.DUMMYFUNCTION("IFERROR( INDEX( FILTER('商品表'!$A:$IV, '商品表'!$A:$A = L33), 1, MATCH(C33 & ""：费用"", '商品表'!$1:$1, 0) ), ""无数据"" ) "),1.2) -> 1.2
A34: ORDER001 | B34: 陆运 | C34: 马来西亚 | D34: 6 | E34: S533 | F34: 黑色 | G34: XL | H34: 50 | I34: 45987 | J34: 2125-52 | K34: {=IFERROR( XLOOKUP(F34, '颜色对照表'!A:A, '颜色对照表'!C:C), IFERROR( XLOOKUP(F34, '颜色对照表'!B:B, '颜色对照表'!C:C), "未匹配到颜色" ) )} -> black | L34: =E34&"_"&K34&"_"&G34 -> S533_black_XL | M34: =IFERROR(__xludf.DUMMYFUNCTION("INDEX(FILTER('对账单'!$E$2:$E1000, '对账单'!$A$2:$A1000 = A34, '对账单'!$G$2:$G1000 = E34),1)"),23.0) -> 23 | N34: =IFERROR(__xludf.DUMMYFUNCTION("IFERROR( INDEX( FILTER('商品表'!$A:$IV, '商品表'!$A:$A = L34), 1, MATCH(C34 & ""：费用"", '商品表'!$1:$1, 0) ), ""无数据"" ) "),1.2) -> 1.2
A35: ORDER001 | B35: 陆运 | C35: 马来西亚 | D35: 6 | E35: S596 | F35: 灰色 | G35: M | H35: 270 | I35: 45987 | J35: 2125-52 | K35: {=IFERROR( XLOOKUP(F35, '颜色对照表'!A:A, '颜色对照表'!C:C), IFERROR( XLOOKUP(F35, '颜色对照表'!B:B, '颜色对照表'!C:C), "未匹配到颜色" ) )} -> gray | L35: =E35&"_"&K35&"_"&G35 -> S596_gray_M | M35: =IFERROR(__xludf.DUMMYFUNCTION("INDEX(FILTER('对账单'!$E$2:$E1000, '对账单'!$A$2:$A1000 = A35, '对账单'!$G$2:$G1000 = E35),1)"),"#N/A") -> #N/A | N35: =IFERROR(__xludf.DUMMYFUNCTION("IFERROR( INDEX( FILTER('商品表'!$A:$IV, '商品表'!$A:$A = L35), 1, MATCH(C35 & ""：费用"", '商品表'!$1:$1, 0) ), ""无数据"" ) "),1.2) -> 1.2
A36: ORDER001 | B36: 陆运 | C36: 马来西亚 | D36: 7 | E36: S596 | F36: 灰色 | G36: XL | H36: 280 | I36: 45987 | J36: 2125-52 | K36: {=IFERROR( XLOOKUP(F36, '颜色对照表'!A:A, '颜色对照表'!C:C), IFERROR( XLOOKUP(F36, '颜色对照表'!B:B, '颜色对照表'!C:C), "未匹配到颜色" ) )} -> gray | L36: =E36&"_"&K36&"_"&G36 -> S596_gray_XL | M36: =IFERROR(__xludf.DUMMYFUNCTION("INDEX(FILTER('对账单'!$E$2:$E1000, '对账单'!$A$2:$A1000 = A36, '对账单'!$G$2:$G1000 = E36),1)"),"#N/A") -> #N/A | N36: =IFERROR(__xludf.DUMMYFUNCTION("IFERROR( INDEX( FILTER('商品表'!$A:$IV, '商品表'!$A:$A = L36), 1, MATCH(C36 & ""：费用"", '商品表'!$1:$1, 0) ), ""无数据"" ) "),1.2) -> 1.2
A37: ORDER001 | B37: 陆运 | C37: 马来西亚 | D37: 8 | E37: S596 | F37: 灰色 | G37: XL | H37: 230 | I37: 45987 | J37: 2125-52 | K37: {=IFERROR( XLOOKUP(F37, '颜色对照表'!A:A, '颜色对照表'!C:C), IFERROR( XLOOKUP(F37, '颜色对照表'!B:B, '颜色对照表'!C:C), "未匹配到颜色" ) )} -> gray | L37: =E37&"_"&K37&"_"&G37 -> S596_gray_XL | M37: =IFERROR(__xludf.DUMMYFUNCTION("INDEX(FILTER('对账单'!$E$2:$E1000, '对账单'!$A$2:$A1000 = A37, '对账单'!$G$2:$G1000 = E37),1)"),"#N/A") -> #N/A | N37: =IFERROR(__xludf.DUMMYFUNCTION("IFERROR( INDEX( FILTER('商品表'!$A:$IV, '商品表'!$A:$A = L37), 1, MATCH(C37 & ""：费用"", '商品表'!$1:$1, 0) ), ""无数据"" ) "),1.2) -> 1.2
A38: ORDER001 | B38: 陆运 | C38: 马来西亚 | D38: 8 | E38: S596 | F38: 灰色 | G38: 2XL | H38: 50 | I38: 45987 | J38: 2125-52 | K38: {=IFERROR( XLOOKUP(F38, '颜色对照表'!A:A, '颜色对照表'!C:C), IFERROR( XLOOKUP(F38, '颜色对照表'!B:B, '颜色对照表'!C:C), "未匹配到颜色" ) )} -> gray | L38: =E38&"_"&K38&"_"&G38 -> S596_gray_2XL | M38: =IFERROR(__xludf.DUMMYFUNCTION("INDEX(FILTER('对账单'!$E$2:$E1000, '对账单'!$A$2:$A1000 = A38, '对账单'!$G$2:$G1000 = E38),1)"),"#N/A") -> #N/A | N38: =IFERROR(__xludf.DUMMYFUNCTION("IFERROR( INDEX( FILTER('商品表'!$A:$IV, '商品表'!$A:$A = L38), 1, MATCH(C38 & ""：费用"", '商品表'!$1:$1, 0) ), ""无数据"" ) "),1.2) -> 1.2
A39: ORDER001 | B39: 陆运 | C39: 马来西亚 | D39: 9 | E39: S596 | F39: 灰色 | G39: 2XL | H39: 150 | I39: 45987 | J39: 2125-52 | K39: {=IFERROR( XLOOKUP(F39, '颜色对照表'!A:A, '颜色对照表'!C:C), IFERROR( XLOOKUP(F39, '颜色对照表'!B:B, '颜色对照表'!C:C), "未匹配到颜色" ) )} -> gray | L39: =E39&"_"&K39&"_"&G39 -> S596_gray_2XL | M39: =IFERROR(__xludf.DUMMYFUNCTION("INDEX(FILTER('对账单'!$E$2:$E1000, '对账单'!$A$2:$A1000 = A39, '对账单'!$G$2:$G1000 = E39),1)"),"#N/A") -> #N/A | N39: =IFERROR(__xludf.DUMMYFUNCTION("IFERROR( INDEX( FILTER('商品表'!$A:$IV, '商品表'!$A:$A = L39), 1, MATCH(C39 & ""：费用"", '商品表'!$1:$1, 0) ), ""无数据"" ) "),1.2) -> 1.2
A40: ORDER001 | B40: 陆运 | C40: 马来西亚 | D40: 9 | E40: S596 | F40: 灰色 | G40: 3XL | H40: 130 | I40: 45987 | J40: 2125-52 | K40: {=IFERROR( XLOOKUP(F40, '颜色对照表'!A:A, '颜色对照表'!C:C), IFERROR( XLOOKUP(F40, '颜色对照表'!B:B, '颜色对照表'!C:C), "未匹配到颜色" ) )} -> gray | L40: =E40&"_"&K40&"_"&G40 -> S596_gray_3XL | M40: =IFERROR(__xludf.DUMMYFUNCTION("INDEX(FILTER('对账单'!$E$2:$E1000, '对账单'!$A$2:$A1000 = A40, '对账单'!$G$2:$G1000 = E40),1)"),"#N/A") -> #N/A | N40: =IFERROR(__xludf.DUMMYFUNCTION("IFERROR( INDEX( FILTER('商品表'!$A:$IV, '商品表'!$A:$A = L40), 1, MATCH(C40 & ""：费用"", '商品表'!$1:$1, 0) ), ""无数据"" ) "),1.2) -> 1.2
...

Sheet 发货明细
A1: 订单ID | B1: 运输方式 | C1: 国家 | D1: 包裹编号 | E1: 货号 | F1: 颜色 | G1: 尺码 | H1: 数量 | I1: 发货日期 | J1: 唛头 | K1: 英文颜色 | L1: 商品编码 | M1: 工厂单价 | N1: 头程费用
A2: ORDER001 | B2: 海运 | C2: 泰国 | D2: 1 | E2: S537 | F2: 白色 | G2: M | H2: 53 | I2: 45987 | J2: 2125-52 | K2: {=IFERROR( XLOOKUP(F2, '颜色对照表'!A:A, '颜色对照表'!C:C), IFERROR( XLOOKUP(F2, '颜色对照表'!B:B, '颜色对照表'!C:C), "未匹配到颜色" ) )} -> white | L2: =E2&"_"&K2&"_"&G2 -> S537_white_M | M2: {=IFERROR( INDEX('对账单'!$E:$E, MATCH( 1, INDEX( ('对账单'!$A:$A=A2)* ('对账单'!$G:$G=E2), 0), 0) ), "无数据" )} -> 33 | N2: {=IFERROR( INDEX('商品表'!$A:$IV, MATCH(L2,'商品表'!$A:$A,0), MATCH(C2 & "：费用",'商品表'!$1:$1,0) ), "无数据" )} -> 1
A3: ORDER001 | B3: 海运 | C3: 马来西亚 | D3: 1 | E3: S537 | F3: 白色 | G3: L | H3: 99 | I3: 45987 | J3: 2125-52 | K3: {=IFERROR( XLOOKUP(F3, '颜色对照表'!A:A, '颜色对照表'!C:C), IFERROR( XLOOKUP(F3, '颜色对照表'!B:B, '颜色对照表'!C:C), "未匹配到颜色" ) )} -> white | L3: =E3&"_"&K3&"_"&G3 -> S537_white_L | M3: {=IFERROR( INDEX('对账单'!$E:$E, MATCH( 1, INDEX( ('对账单'!$A:$A=A3)* ('对账单'!$G:$G=E3), 0), 0) ), "无数据" )} -> 33 | N3: {=IFERROR( INDEX('商品表'!$A:$IV, MATCH(L3,'商品表'!$A:$A,0), MATCH(C3 & "：费用",'商品表'!$1:$1,0) ), "无数据" )} -> 1.2
A4: ORDER001 | B4: 海运 | C4: 马来西亚 | D4: 1 | E4: S537 | F4: 黑色 | G4: L | H4: 68 | I4: 45987 | J4: 2125-52 | K4: {=IFERROR( XLOOKUP(F4, '颜色对照表'!A:A, '颜色对照表'!C:C), IFERROR( XLOOKUP(F4, '颜色对照表'!B:B, '颜色对照表'!C:C), "未匹配到颜色" ) )} -> black | L4: =E4&"_"&K4&"_"&G4 -> S537_black_L | M4: {=IFERROR( INDEX('对账单'!$E:$E, MATCH( 1, INDEX( ('对账单'!$A:$A=A4)* ('对账单'!$G:$G=E4), 0), 0) ), "无数据" )} -> 33 | N4: {=IFERROR( INDEX('商品表'!$A:$IV, MATCH(L4,'商品表'!$A:$A,0), MATCH(C4 & "：费用",'商品表'!$1:$1,0) ), "无数据" )} -> 1.2
A5: ORDER001 | B5: 海运 | C5: 马来西亚 | D5: 1 | E5: S537 | F5: 黑色 | G5: 2XL | H5: 68 | I5: 45987 | J5: 2125-52 | K5: {=IFERROR( XLOOKUP(F5, '颜色对照表'!A:A, '颜色对照表'!C:C), IFERROR( XLOOKUP(F5, '颜色对照表'!B:B, '颜色对照表'!C:C), "未匹配到颜色" ) )} -> black | L5: =E5&"_"&K5&"_"&G5 -> S537_black_2XL | M5: {=IFERROR( INDEX('对账单'!$E:$E, MATCH( 1, INDEX( ('对账单'!$A:$A=A5)* ('对账单'!$G:$G=E5), 0), 0) ), "无数据" )} -> 33 | N5: {=IFERROR( INDEX('商品表'!$A:$IV, MATCH(L5,'商品表'!$A:$A,0), MATCH(C5 & "：费用",'商品表'!$1:$1,0) ), "无数据" )} -> 1.2
A6: ORDER001 | B6: 海运 | C6: 马来西亚 | D6: 1 | E6: S537 | F6: 黑色 | G6: 3XL | H6: 69 | I6: 45987 | J6: 2125-52 | K6: {=IFERROR( XLOOKUP(F6, '颜色对照表'!A:A, '颜色对照表'!C:C), IFERROR( XLOOKUP(F6, '颜色对照表'!B:B, '颜色对照表'!C:C), "未匹配到颜色" ) )} -> black | L6: =E6&"_"&K6&"_"&G6 -> S537_black_3XL | M6: {=IFERROR( INDEX('对账单'!$E:$E, MATCH( 1, INDEX( ('对账单'!$A:$A=A6)* ('对账单'!$G:$G=E6), 0), 0) ), "无数据" )} -> 33 | N6: {=IFERROR( INDEX('商品表'!$A:$IV, MATCH(L6,'商品表'!$A:$A,0), MATCH(C6 & "：费用",'商品表'!$1:$1,0) ), "无数据" )} -> 1.2
A7: ORDER001 | B7: 海运 | C7: 马来西亚 | D7: 2 | E7: S537 | F7: 黑色 | G7: 3XL | H7: 50 | I7: 45987 | J7: 2125-52 | K7: {=IFERROR( XLOOKUP(F7, '颜色对照表'!A:A, '颜色对照表'!C:C), IFERROR( XLOOKUP(F7, '颜色对照表'!B:B, '颜色对照表'!C:C), "未匹配到颜色" ) )} -> black | L7: =E7&"_"&K7&"_"&G7 -> S537_black_3XL | M7: {=IFERROR( INDEX('对账单'!$E:$E, MATCH( 1, INDEX( ('对账单'!$A:$A=A7)* ('对账单'!$G:$G=E7), 0), 0) ), "无数据" )} -> 33 | N7: {=IFERROR( INDEX('商品表'!$A:$IV, MATCH(L7,'商品表'!$A:$A,0), MATCH(C7 & "：费用",'商品表'!$1:$1,0) ), "无数据" )} -> 1.2
A8: ORDER001 | B8: 海运 | C8: 马来西亚 | D8: 2 | E8: S596 | F8: 灰色 | G8: L | H8: 272 | I8: 45987 | J8: 2125-52 | K8: {=IFERROR( XLOOKUP(F8, '颜色对照表'!A:A, '颜色对照表'!C:C), IFERROR( XLOOKUP(F8, '颜色对照表'!B:B, '颜色对照表'!C:C), "未匹配到颜色" ) )} -> gray | L8: =E8&"_"&K8&"_"&G8 -> S596_gray_L | M8: {=IFERROR( INDEX('对账单'!$E:$E, MATCH( 1, INDEX( ('对账单'!$A:$A=A8)* ('对账单'!$G:$G=E8), 0), 0) ), "无数据" )} -> 无数据 | N8: {=IFERROR( INDEX('商品表'!$A:$IV, MATCH(L8,'商品表'!$A:$A,0), MATCH(C8 & "：费用",'商品表'!$1:$1,0) ), "无数据" )} -> 1.2
A9: ORDER001 | B9: 陆运 | C9: 马来西亚 | D9: 1 | E9: S537 | F9: 白色 | G9: 3XL | H9: 92 | I9: 45987 | J9: 2125-52 | K9: {=IFERROR( XLOOKUP(F9, '颜色对照表'!A:A, '颜色对照表'!C:C), IFERROR( XLOOKUP(F9, '颜色对照表'!B:B, '颜色对照表'!C:C), "未匹配到颜色" ) )} -> white | L9: =E9&"_"&K9&"_"&G9 -> S537_white_3XL | M9: {=IFERROR( INDEX('对账单'!$E:$E, MATCH( 1, INDEX( ('对账单'!$A:$A=A9)* ('对账单'!$G:$G=E9), 0), 0) ), "无数据" )} -> 33 | N9: {=IFERROR( INDEX('商品表'!$A:$IV, MATCH(L9,'商品表'!$A:$A,0), MATCH(C9 & "：费用",'商品表'!$1:$1,0) ), "无数据" )} -> 1.2
A10: ORDER001 | B10: 陆运 | C10: 马来西亚 | D10: 1 | E10: S671 | F10: 黑色 | G10: M | H10: 98 | I10: 45987 | J10: 2125-52 | K10: {=IFERROR( XLOOKUP(F10, '颜色对照表'!A:A, '颜色对照表'!C:C), IFERROR( XLOOKUP(F10, '颜色对照表'!B:B, '颜色对照表'!C:C), "未匹配到颜色" ) )} -> black | L10: =E10&"_"&K10&"_"&G10 -> S671_black_M | M10: {=IFERROR( INDEX('对账单'!$E:$E, MATCH( 1, INDEX( ('对账单'!$A:$A=A10)* ('对账单'!$G:$G=E10), 0), 0) ), "无数据" )} -> 25 | N10: {=IFERROR( INDEX('商品表'!$A:$IV, MATCH(L10,'商品表'!$A:$A,0), MATCH(C10 & "：费用",'商品表'!$1:$1,0) ), "无数据" )} -> 1.2
A11: ORDER001 | B11: 陆运 | C11: 马来西亚 | D11: 1 | E11: S671 | F11: 黑色 | G11: L | H11: 100 | I11: 45987 | J11: 2125-52 | K11: {=IFERROR( XLOOKUP(F11, '颜色对照表'!A:A, '颜色对照表'!C:C), IFERROR( XLOOKUP(F11, '颜色对照表'!B:B, '颜色对照表'!C:C), "未匹配到颜色" ) )} -> black | L11: =E11&"_"&K11&"_"&G11 -> S671_black_L | M11: {=IFERROR( INDEX('对账单'!$E:$E, MATCH( 1, INDEX( ('对账单'!$A:$A=A11)* ('对账单'!$G:$G=E11), 0), 0) ), "无数据" )} -> 25 | N11: {=IFERROR( INDEX('商品表'!$A:$IV, MATCH(L11,'商品表'!$A:$A,0), MATCH(C11 & "：费用",'商品表'!$1:$1,0) ), "无数据" )} -> 1.2
A12: ORDER001 | B12: 陆运 | C12: 马来西亚 | D12: 1 | E12: S671 | F12: 黑色 | G12: 2XL | H12: 10 | I12: 45987 | J12: 2125-52 | K12: {=IFERROR( XLOOKUP(F12, '颜色对照表'!A:A, '颜色对照表'!C:C), IFERROR( XLOOKUP(F12, '颜色对照表'!B:B, '颜色对照表'!C:C), "未匹配到颜色" ) )} -> black | L12: =E12&"_"&K12&"_"&G12 -> S671_black_2XL | M12: {=IFERROR( INDEX('对账单'!$E:$E, MATCH( 1, INDEX( ('对账单'!$A:$A=A12)* ('对账单'!$G:$G=E12), 0), 0) ), "无数据" )} -> 25 | N12: {=IFERROR( INDEX('商品表'!$A:$IV, MATCH(L12,'商品表'!$A:$A,0), MATCH(C12 & "：费用",'商品表'!$1:$1,0) ), "无数据" )} -> 1.2
A13: ORDER001 | B13: 陆运 | C13: 马来西亚 | D13: 2 | E13: S671 | F13: 黑色 | G13: 2XL | H13: 140 | I13: 45987 | J13: 2125-52 | K13: {=IFERROR( XLOOKUP(F13, '颜色对照表'!A:A, '颜色对照表'!C:C), IFERROR( XLOOKUP(F13, '颜色对照表'!B:B, '颜色对照表'!C:C), "未匹配到颜色" ) )} -> black | L13: =E13&"_"&K13&"_"&G13 -> S671_black_2XL | M13: {=IFERROR( INDEX('对账单'!$E:$E, MATCH( 1, INDEX( ('对账单'!$A:$A=A13)* ('对账单'!$G:$G=E13), 0), 0) ), "无数据" )} -> 25 | N13: {=IFERROR( INDEX('商品表'!$A:$IV, MATCH(L13,'商品表'!$A:$A,0), MATCH(C13 & "：费用",'商品表'!$1:$1,0) ), "无数据" )} -> 1.2
... A44: ORDER001 | B44: 陆运 | C44: 马来西亚 | D44: 11 | E44: S596 | F44: 灰色 | G44: L | H44: 190 | I44: 45987 | J44: 2125-52 | K44: {=IFERROR( XLOOKUP(F44, '颜色对照表'!A:A, '颜色对照表'!C:C), IFERROR( XLOOKUP(F44, '颜色对照表'!B:B, '颜色对照表'!C:C), "未匹配到颜色" ) )} -> gray | L44: =E44&"_"&K44&"_"&G44 -> S596_gray_L | M44: {=IFERROR( INDEX('对账单'!$E:$E, MATCH( 1, INDEX( ('对账单'!$A:$A=A44)* ('对账单'!$G:$G=E44), 0), 0) ), "无数据" )} -> 无数据 | N44: {=IFERROR( INDEX('商品表'!$A:$IV, MATCH(L44,'商品表'!$A:$A,0), MATCH(C44 & "：费用",'商品表'!$1:$1,0) ), "无数据" )} -> 1.2

Sheet 对账单
A1: 订单ID | B1: 日期 | C1: 款式 | D1: 数量 | E1: 单价 | F1: 金额 | G1: 货号
A2: ORDER001 | B2: 45987 | C2: 596色布 | D2: 2050 | E2: 22 | F2: 45100 | G2: =LEFT(C2,IF(IFERROR(CODE(MID(C2,1,1)),0)>127,0,IF(IFERROR(CODE(MID(C2,2,1)),0)>127,1,IF(IFERROR(CODE(MID(C2,3,1)),0)>127,2,IF(IFERROR(CODE(MID(C2,4,1)),0)>127,3,IF(IFERROR(CODE(MID(C2,5,1)),0)>127,4,LEN(C2))))))) -> 596
A3: ORDER001 | B3: 45987 | C3: S537 | D3: 499 | E3: 33 | F3: 16467 | G3: =LEFT(C3,IF(IFERROR(CODE(MID(C3,1,1)),0)>127,0,IF(IFERROR(CODE(MID(C3,2,1)),0)>127,1,IF(IFERROR(CODE(MID(C3,3,1)),0)>127,2,IF(IFERROR(CODE(MID(C3,4,1)),0)>127,3,IF(IFERROR(CODE(MID(C3,5,1)),0)>127,4,LEN(C3))))))) -> S537
A4: ORDER001 | B4: 45987 | C4: S671黑色 | D4: 348 | E4: 25 | F4: 8700 | G4: =LEFT(C4,IF(IFERROR(CODE(MID(C4,1,1)),0)>127,0,IF(IFERROR(CODE(MID(C4,2,1)),0)>127,1,IF(IFERROR(CODE(MID(C4,3,1)),0)>127,2,IF(IFERROR(CODE(MID(C4,4,1)),0)>127,3,IF(IFERROR(CODE(MID(C4,5,1)),0)>127,4,LEN(C4))))))) -> S671
A5: ORDER001 | B5: 45987 | C5: S546黑色 | D5: 204 | E5: 32 | F5: 6528 | G5: =LEFT(C5,IF(IFERROR(CODE(MID(C5,1,1)),0)>127,0,IF(IFERROR(CODE(MID(C5,2,1)),0)>127,1,IF(IFERROR(CODE(MID(C5,3,1)),0)>127,2,IF(IFERROR(CODE(MID(C5,4,1)),0)>127,3,IF(IFERROR(CODE(MID(C5,5,1)),0)>127,4,LEN(C5))))))) -> S546
A6: ORDER001 | B6: 45987 | C6: S539 | D6: 169 | E6: 12 | F6: 2028 | G6: =LEFT(C6,IF(IFERROR(CODE(MID(C6,1,1)),0)>127,0,IF(IFERROR(CODE(MID(C6,2,1)),0)>127,1,IF(IFERROR(CODE(MID(C6,3,1)),0)>127,2,IF(IFERROR(CODE(MID(C6,4,1)),0)>127,3,IF(IFERROR(CODE(MID(C6,5,1)),0)>127,4,LEN(C6))))))) -> S539
A7: ORDER001 | B7: 45987 | C7: S568 | D7: 198 | E7: 26 | F7: 5148 | G7: =LEFT(C7,IF(IFERROR(CODE(MID(C7,1,1)),0)>127,0,IF(IFERROR(CODE(MID(C7,2,1)),0)>127,1,IF(IFERROR(CODE(MID(C7,3,1)),0)>127,2,IF(IFERROR(CODE(MID(C7,4,1)),0)>127,3,IF(IFERROR(CODE(MID(C7,5,1)),0)>127,4,LEN(C7))))))) -> S568
A8: ORDER001 | B8: 45987 | C8: S516 | D8: 237 | E8: 22 | F8: 5214 | G8: =LEFT(C8,IF(IFERROR(CODE(MID(C8,1,1)),0)>127,0,IF(IFERROR(CODE(MID(C8,2,1)),0)>127,1,IF(IFERROR(CODE(MID(C8,3,1)),0)>127,2,IF(IFERROR(CODE(MID(C8,4,1)),0)>127,3,IF(IFERROR(CODE(MID(C8,5,1)),0)>127,4,LEN(C8))))))) -> S516
A9: ORDER001 | B9: 45987 | C9: S533 | D9: 137 | E9: 23 | F9: 3151 | G9: =LEFT(C9,IF(IFERROR(CODE(MID(C9,1,1)),0)>127,0,IF(IFERROR(CODE(MID(C9,2,1)),0)>127,1,IF(IFERROR(CODE(MID(C9,3,1)),0)>127,2,IF(IFERROR(CODE(MID(C9,4,1)),0)>127,3,IF(IFERROR(CODE(MID(C9,5,1)),0)>127,4,LEN(C9))))))) -> S533

Sheet 入库单
A1: 订单ID | B1: 商品编码 | C1: 系统采购单价 | D1: 头程费用 | E1: 调拨费用 | F1: 预计数量 | G1: 工厂单价 | H1: 系统录入状态 | I1: 工厂录入状态 | J1: 价格核对状态
A2: ORDER001 | B2: S537_white_M | C2: {=IFERROR( XLOOKUP(B2, '商品表'!A:A, '商品表'!AN:AN), -1 )} -> 10 | D2: {=IFERROR( XLOOKUP(B2, '商品表'!A:A, '商品表'!DG:DG), -1 )} -> 1.2 | F2: =IFERROR( IF(C2 = -1, -1, IF(D2 = -1, -1, SUMIFS('发货明细'!$H:$H, '发货明细 -demo'!$A:$A, A2, '发货明细 -demo'!$L:$L, B2) ) ), -1 ) -> 53 | G2: {=IFERROR( INDEX('发货明细'!M:M, MATCH(1, (A2='发货明细 -demo'!A:A) * (B2='发货明细 -demo'!L:L), 0) ), -1 )} -> 33 | H2: =IF(C2=-1,"异常","正常") -> 正常 | I2: =IF(G2=-1,"异常","正常") -> 正常 | J2: =IF(AND(C2>=G2,H2="正常",I2="正常"),"正常","异常") -> 异常
A3: ORDER001 | B3: S537_white_L | C3: {=IFERROR( XLOOKUP(B3, '商品表'!A:A, '商品表'!AN:AN), -1 )} -> 11 | D3: {=IFERROR( XLOOKUP(B3, '商品表'!A:A, '商品表'!DG:DG), -1 )} -> 1.2 | F3: =IFERROR( IF(C3 = -1, -1, IF(D3 = -1, -1, SUMIFS('发货明细'!$H:$H, '发货明细 -demo'!$A:$A, A3, '发货明细 -demo'!$L:$L, B3) ) ), -1 ) -> 99 | G3: {=IFERROR( INDEX('发货明细'!M:M, MATCH(1, (A3='发货明细 -demo'!A:A) * (B3='发货明细 -demo'!L:L), 0) ), -1 )} -> 33 | H3: =IF(C3=-1,"异常","正常") -> 正常 | I3: =IF(G3=-1,"异常","正常") -> 正常 | J3: =IF(AND(C3>=G3,H3="正常",I3="正常"),"正常","异常") -> 异常
A4: ORDER001 | B4: S537_black_L | C4: {=IFERROR( XLOOKUP(B4, '商品表'!A:A, '商品表'!AN:AN), -1 )} -> 12 | D4: {=IFERROR( XLOOKUP(B4, '商品表'!A:A, '商品表'!DG:DG), -1 )} -> 1.2 | F4: =IFERROR( IF(C4 = -1, -1, IF(D4 = -1, -1, SUMIFS('发货明细'!$H:$H, '发货明细 -demo'!$A:$A, A4, '发货明细 -demo'!$L:$L, B4) ) ), -1 ) -> 68 | G4: {=IFERROR( INDEX('发货明细'!M:M, MATCH(1, (A4='发货明细 -demo'!A:A) * (B4='发货明细 -demo'!L:L), 0) ), -1 )} -> 33 | H4: =IF(C4=-1,"异常","正常") -> 正常 | I4: =IF(G4=-1,"异常","正常") -> 正常 | J4: =IF(AND(C4>=G4,H4="正常",I4="正常"),"正常","异常") -> 异常

Sheet 入库单（副本）
A1: 订单ID | B1: 商品编码 | C1: 系统采购单价 | D1: 头程费用 | E1: 调拨费用 | F1: 预计数量 | G1: 工厂单价 | H1: 系统录入状态 | I1: 工厂录入状态 | J1: 价格核对状态
A2: ORDER001 | B2: S537_white_M | C2: {=IFERROR( XLOOKUP(B2, '商品表'!A:A, '商品表'!AN:AN), -1 )} -> 10 | D2: {=IFERROR( XLOOKUP(B2, '商品表'!A:A, '商品表'!DG:DG), -1 )} -> 1.2 | F2: =IFERROR(__xludf.DUMMYFUNCTION("IF( OR(C2=-1, D2=-1), -1, SUM( FILTER('发货明细'!H:H, ('发货明细'!A:A = A2) * ('发货明细'!L:L = B2) ) ) ) "),53.0) -> 53 | G2: =IFERROR(__xludf.DUMMYFUNCTION("IFERROR(INDEX(FILTER('发货明细'!$M$2:$M1000, '发货明细'!$A$2:$A1000 = A2, '发货明细'!$L$2:$L1000 = B2),1),-1)"),33.0) -> 33 | H2: =IF(C2=-1,"异常","正常") -> 正常 | I2: =IF(G2=-1,"异常","正常") -> 正常 | J2: =IF(AND(C2>=G2,H2="正常",I2="正常"),"正常","异常") -> 异常
A3: ORDER001 | B3: S537_white_L | C3: {=IFERROR( XLOOKUP(B3, '商品表'!A:A, '商品表'!AN:AN), -1 )} -> 11 | D3: {=IFERROR( XLOOKUP(B3, '商品表'!A:A, '商品表'!DG:DG), -1 )} -> 1.2 | F3: =IFERROR(__xludf.DUMMYFUNCTION("IF( OR(C3=-1, D3=-1), -1, SUM( FILTER('发货明细'!H:H, ('发货明细'!A:A = A3) * ('发货明细'!L:L = B3) ) ) ) "),99.0) -> 99 | G3: =IFERROR(__xludf.DUMMYFUNCTION("IFERROR(INDEX(FILTER('发货明细'!$M$2:$M1000, '发货明细'!$A$2:$A1000 = A3, '发货明细'!$L$2:$L1000 = B3),1),-1)"),33.0) -> 33 | H3: =IF(C3=-1,"异常","正常") -> 正常 | I3: =IF(G3=-1,"异常","正常") -> 正常 | J3: =IF(AND(C3>=G3,H3="正常",I3="正常"),"正常","异常") -> 异常
A4: ORDER001 | B4: S537_black_L | C4: {=IFERROR( XLOOKUP(B4, '商品表'!A:A, '商品表'!AN:AN), -1 )} -> 12 | D4: {=IFERROR( XLOOKUP(B4, '商品表'!A:A, '商品表'!DG:DG), -1 )} -> 1.2 | F4: =IFERROR(__xludf.DUMMYFUNCTION("IF( OR(C4=-1, D4=-1), -1, SUM( FILTER('发货明细'!H:H, ('发货明细'!A:A = A4) * ('发货明细'!L:L = B4) ) ) ) "),68.0) -> 68 | G4: =IFERROR(__xludf.DUMMYFUNCTION("IFERROR(INDEX(FILTER('发货明细'!$M$2:$M1000, '发货明细'!$A$2:$A1000 = A4, '发货明细'!$L$2:$L1000 = B4),1),-1)"),33.0) -> 33 | H4: =IF(C4=-1,"异常","正常") -> 正常 | I4: =IF(G4=-1,"异常","正常") -> 正常 | J4: =IF(AND(C4>=G4,H4="正常",I4="正常"),"正常","异常") -> 异常
